<?xml version="1.0" encoding="utf-8"?>
<robot name="whc" xmlns:xacro="http://ros.org/wiki/xacro">

  <link name="base_footprint"/>

  <joint name="base_footprint_joint" type="fixed">
    <parent link="base_footprint"/>
    <child link="base_link"/>
    <origin xyz="0 0 0" rpy="0 0 0"/>
  </joint>

  <link name="base_link">
    <inertial>
      <origin xyz="0.0 0.0 0.57" rpy="0 0 0"/>
      <mass value="13000.0"/> 
      <inertia
        ixx="4016.5523" ixy="-4.901" ixz="-30.883"
        iyy="3912.0301" iyz="2.0478" izz="7532.1244"/> 
    </inertial>
    
    <visual>
      <origin xyz="0 0 0" rpy="0 0 0"/>
      <geometry>
        <mesh filename="file://$(find whc_description)/meshes/base_link.STL"/>
      </geometry>
      <material name="">
        <color rgba="0.5 0.5 0.5 1"/>
      </material>
    </visual>
    
    <collision>
      <origin xyz="0 0 0" rpy="0 0 0"/>
      <geometry>
        <mesh filename="file://$(find whc_description)/meshes/base_link.STL"/>
      </geometry>
    </collision>
  </link>

  <link name="left_wheel_back">
    <inertial>
      <mass value="500.0"/>
      <origin xyz="0 0 0"/>
      <inertia ixx="36.8" ixy="0.0" ixz="0.0"
               iyy="34.6" iyz="0.0"
               izz="36.8"/>
    </inertial>
    
    <visual>
      <origin xyz="0 0 0" rpy="1.5708 0 0"/>
      <geometry>
        <cylinder length="0.3" radius="0.48"/>
      </geometry>
      <material name="">
        <color rgba="0.5 0.5 0.5 1"/>
      </material>
    </visual>
    
    <collision>
      <origin xyz="0 0 0" rpy="1.5708 0 0"/>
      <geometry>
        <cylinder length="0.3" radius="0.48"/>
      </geometry>
    </collision>
  </link>

  <link name="left_wheel_middle">
    <inertial>
      <mass value="500.0"/>
      <origin xyz="0 0 0"/>
      <inertia ixx="36.8" ixy="0.0" ixz="0.0"
               iyy="34.6" iyz="0.0"
               izz="36.8"/>
    </inertial>
    
    <visual>
      <origin xyz="0 0 0" rpy="1.5708 0 0"/>
      <geometry>
        <cylinder length="0.3" radius="0.48"/>
      </geometry>
      <material name="">
        <color rgba="0.5 0.5 0.5 1"/>
      </material>
    </visual>
    
    <collision>
      <origin xyz="0 0 0" rpy="1.5708 0 0"/>
      <geometry>
        <cylinder length="0.3" radius="0.48"/>
      </geometry>
    </collision>
  </link>

  <link name="left_wheel_middle1">
    <inertial>
      <mass value="500.0"/>
      <origin xyz="0 0 0"/>
      <inertia ixx="36.8" ixy="0.0" ixz="0.0"
               iyy="34.6" iyz="0.0"
               izz="36.8"/>
    </inertial>
    
    <visual>
      <origin xyz="0 0 0" rpy="1.5708 0 0"/>
      <geometry>
        <cylinder length="0.3" radius="0.48"/>
      </geometry>
      <material name="">
        <color rgba="0.5 0.5 0.5 1"/>
      </material>
    </visual>
    
    <collision>
      <origin xyz="0 0 0" rpy="1.5708 0 0"/>
      <geometry>
        <cylinder length="0.3" radius="0.48"/>
      </geometry>
    </collision>
  </link>

  <link name="left_wheel_middle2">
    <inertial>
      <mass value="500.0"/>
      <origin xyz="0 0 0"/>
      <inertia ixx="36.8" ixy="0.0" ixz="0.0"
               iyy="34.6" iyz="0.0"
               izz="36.8"/>
    </inertial>
    
    <visual>
      <origin xyz="0 0 0" rpy="1.5708 0 0"/>
      <geometry>
        <cylinder length="0.3" radius="0.48"/>
      </geometry>
      <material name="">
        <color rgba="0.5 0.5 0.5 1"/>
      </material>
    </visual>
    
    <collision>
      <origin xyz="0 0 0" rpy="1.5708 0 0"/>
      <geometry>
        <cylinder length="0.3" radius="0.48"/>
      </geometry>
    </collision>
  </link>

  
  <link name="left_wheel_front">
    <inertial>
      <mass value="500.0"/>
      <origin xyz="0 0 0"/>
      <inertia ixx="36.8" ixy="0.0" ixz="0.0"
               iyy="34.6" iyz="0.0"
               izz="36.8"/>
    </inertial>
    
    <visual>
      <origin xyz="0 0 0" rpy="1.5708 0 0"/>
      <geometry>
        <cylinder length="0.3" radius="0.48"/>
      </geometry>
      <material name="">
        <color rgba="0.5 0.5 0.5 1"/>
      </material>
    </visual>
    
    <collision>
      <origin xyz="0 0 0" rpy="1.5708 0 0"/>
      <geometry>
        <cylinder length="0.3" radius="0.48"/>
      </geometry>
    </collision>
  </link>

  <link name="right_wheel_back">
    <inertial>
      <mass value="500.0"/>
      <origin xyz="0 0 0"/>
      <inertia ixx="36.8" ixy="0.0" ixz="0.0"
               iyy="34.6" iyz="0.0"
               izz="36.8"/>
    </inertial>
    
    <visual>
      <origin xyz="0 0 0" rpy="1.5708 0 0"/>
      <geometry>
        <cylinder length="0.3" radius="0.48"/>
      </geometry>
      <material name="">
        <color rgba="0.5 0.5 0.5 1"/>
      </material>
    </visual>
    
    <collision>
      <origin xyz="0 0 0" rpy="1.5708 0 0"/>
      <geometry>
        <cylinder length="0.3" radius="0.48"/>
      </geometry>
    </collision>
  </link>

  <link name="right_wheel_middle">
    <inertial>
      <mass value="500.0"/>
      <origin xyz="0 0 0"/>
      <inertia ixx="36.8" ixy="0.0" ixz="0.0"
               iyy="34.6" iyz="0.0"
               izz="36.8"/>
    </inertial>
    
    <visual>
      <origin xyz="0 0 0" rpy="1.5708 0 0"/>
      <geometry>
        <cylinder length="0.3" radius="0.48"/>
      </geometry>
      <material name="">
        <color rgba="0.5 0.5 0.5 1"/>
      </material>
    </visual>
    
    <collision>
      <origin xyz="0 0 0" rpy="1.5708 0 0"/>
      <geometry>
        <cylinder length="0.3" radius="0.48"/>
      </geometry>
    </collision>
  </link>

  <link name="right_wheel_middle1">
    <inertial>
      <mass value="500.0"/>
      <origin xyz="0 0 0"/>
      <inertia ixx="36.8" ixy="0.0" ixz="0.0"
               iyy="34.6" iyz="0.0"
               izz="36.8"/>
    </inertial>
    
    <visual>
      <origin xyz="0 0 0" rpy="1.5708 0 0"/>
      <geometry>
        <cylinder length="0.3" radius="0.48"/>
      </geometry>
      <material name="">
        <color rgba="0.5 0.5 0.5 1"/>
      </material>
    </visual>
    
    <collision>
      <origin xyz="0 0 0" rpy="1.5708 0 0"/>
      <geometry>
        <cylinder length="0.3" radius="0.48"/>
      </geometry>
    </collision>
  </link>

  <link name="right_wheel_middle2">
    <inertial>
      <mass value="500.0"/>
      <origin xyz="0 0 0"/>
      <inertia ixx="36.8" ixy="0.0" ixz="0.0"
               iyy="34.6" iyz="0.0"
               izz="36.8"/>
    </inertial>
    
    <visual>
      <origin xyz="0 0 0" rpy="1.5708 0 0"/>
      <geometry>
        <cylinder length="0.3" radius="0.48"/>
      </geometry>
      <material name="">
        <color rgba="0.5 0.5 0.5 1"/>
      </material>
    </visual>
    
    <collision>
      <origin xyz="0 0 0" rpy="1.5708 0 0"/>
      <geometry>
        <cylinder length="0.3" radius="0.48"/>
      </geometry>
    </collision>
  </link>
 
  <link name="right_wheel_front">
    <inertial>
      <mass value="500.0"/>
      <origin xyz="0 0 0"/>
      <inertia ixx="36.8" ixy="0.0" ixz="0.0"
               iyy="34.6" iyz="0.0"
               izz="36.8"/>
    </inertial>
    
    <visual>
      <origin xyz="0 0 0" rpy="1.5708 0 0"/>
      <geometry>
        <cylinder length="0.3" radius="0.48"/>
      </geometry>
      <material name="">
        <color rgba="0.5 0.5 0.5 1"/>
      </material>
    </visual>
    
    <collision>
      <origin xyz="0 0 0" rpy="1.5708 0 0"/>
      <geometry>
        <cylinder length="0.3" radius="0.48"/>
      </geometry>
    </collision>
  </link>

  <joint name="left_wheel_front_joint" type="continuous">
    <parent link="base_link"/>
    <child link="left_wheel_front"/>
    <origin xyz="2.0 1.4 0.47" rpy="0 0 0"/>
    <axis xyz="0 1 0"/>
    <dynamics damping="50.0" friction="1500.0"/> 
  </joint>
  
  <joint name="left_wheel_middle_joint" type="continuous">
    <parent link="base_link"/>
    <child link="left_wheel_middle"/>
    <origin xyz="0 1.4 0.47" rpy="0 0 0"/>
    <axis xyz="0 1 0"/>
    <dynamics damping="50.0" friction="1500.0"/> 
  </joint>

  <joint name="left_wheel_middle1_joint" type="continuous">
    <parent link="base_link"/>
    <child link="left_wheel_middle1"/>
    <origin xyz="1 1.4 0.47" rpy="0 0 0"/>
    <axis xyz="0 1 0"/>
    <dynamics damping="50.0" friction="1500.0"/> 
  </joint>

  <joint name="left_wheel_middle2_joint" type="continuous">
    <parent link="base_link"/>
    <child link="left_wheel_middle2"/>
    <origin xyz="-1 1.4 0.47" rpy="0 0 0"/>
    <axis xyz="0 1 0"/>
    <dynamics damping="50.0" friction="1500.0"/> 
  </joint>

  <joint name="left_wheel_back_joint" type="continuous">
    <parent link="base_link"/>
    <child link="left_wheel_back"/>
    <origin xyz="-2.0 1.4 0.47" rpy="0 0 0"/>
    <axis xyz="0 1 0"/>
    <dynamics damping="50.0" friction="1500.0"/>
  </joint>
 
  <joint name="right_wheel_back_joint" type="continuous">
    <parent link="base_link"/>
    <child link="right_wheel_back"/>
    <origin xyz="-2.0 -1.4 0.47" rpy="0 0 0"/>
    <axis xyz="0 1 0"/>
    <dynamics damping="50.0" friction="1500.0"/>
  </joint>

  <joint name="right_wheel_middle_joint" type="continuous">
    <parent link="base_link"/>
    <child link="right_wheel_middle"/>
    <origin xyz="0 -1.4 0.47" rpy="0 0 0"/>
    <axis xyz="0 1 0"/>
    <dynamics damping="50.0" friction="1500.0"/>
  </joint>

  <joint name="right_wheel_middle1_joint" type="continuous">
    <parent link="base_link"/>
    <child link="right_wheel_middle1"/>
    <origin xyz="1 -1.4 0.47" rpy="0 0 0"/>
    <axis xyz="0 1 0"/>
    <dynamics damping="50.0" friction="1500.0"/>
  </joint>

  <joint name="right_wheel_middle2_joint" type="continuous">
    <parent link="base_link"/>
    <child link="right_wheel_middle2"/>
    <origin xyz="-1 -1.4 0.47" rpy="0 0 0"/>
    <axis xyz="0 1 0"/>
    <dynamics damping="50.0" friction="1500.0"/>
  </joint>
  
  <joint name="right_wheel_front_joint" type="continuous">
    <parent link="base_link"/>
    <child link="right_wheel_front"/>
    <origin xyz="2.0 -1.4 0.47" rpy="0 0 0"/>
    <axis xyz="0 1 0"/>
    <dynamics damping="50.0" friction="1500.0"/>
  </joint>

  <!-- 机械臂部分 -->
  <link name="link1">
    <inertial>
      <origin xyz="-0.3 0 -0.9" rpy="0 0 0" />
      <mass value="6000" />
      <inertia
        ixx="30.265884234048"
        ixy="-0.073592991562754"
        ixz="-11.1888755102849"
        iyy="293.340564525472"
        iyz="-0.0204225769392412"
        izz="315.087329803736" />
    </inertial>
    <visual> 
      <origin xyz="0 0 0" rpy="0 0 0" />
      <geometry>
        <mesh filename="file://$(find whc_description)/meshes/PingTai.STL" />
      </geometry>
      <material name="">
        <color rgba="0.5 0.5 0.5 1"/>
      </material>
    </visual>
    <collision>
      <origin xyz="0 0 0" rpy="0 0 0" />
      <geometry>
        <mesh filename="file://$(find whc_description)/meshes/PingTai.STL" />
      </geometry>
    </collision>
  </link>
  
  <joint name="joint1" type="revolute">
    <origin xyz="0 0 2.313" rpy="0 0 0" />
    <parent link="base_link" />
    <child link="link1" />
    <axis xyz="0 0 1" />
    <limit lower="-3.14" upper="3.14" effort="100" velocity="5" />
  </joint>
   
  <link name="link2">
    <inertial>
      <origin xyz="1.163 -0.067 0.000" rpy="0 0 0" />
      <mass value="1280" />
      <inertia
        ixx="12.724" ixy="-5.424" ixz="-0.060"
        iyy="152.852" iyz="0.004" izz="149.370" />
    </inertial>
    <visual>
      <origin xyz="0 0 0" rpy="0 0 0" />
      <geometry>
        <mesh filename="file://$(find whc_description)/meshes/DaBi.STL" />
      </geometry>
      <material name="">
        <color rgba="0.5 0.5 0.5 1"/>
      </material>
    </visual>
    <collision>
      <origin xyz="0 0 0" rpy="0 0 0" />
      <geometry>
        <mesh filename="file://$(find whc_description)/meshes/DaBi.STL" />
      </geometry>
    </collision>
  </link>
  
  <joint name="joint2" type="revolute">
    <origin xyz="1.65 0 0" rpy="-1.5708 -2.760 0" />
    <parent link="link1" />
    <child link="link2" />
    <axis xyz="0 0 1" />
    <limit lower="0" upper="1.1687" effort="100" velocity="5" />
  </joint>
  
  <link name="link3">
    <inertial>
      <origin xyz="1.19 -0.104 0" rpy="0 0 0" />
      <mass value="1402" />
      <inertia
        ixx="10.4997" ixy="-6.4192" ixz="-1.5167"
        iyy="111.1078" iyz="0" izz="110.0485" />
    </inertial>
    <visual>
      <origin xyz="0 0 0" rpy="0 0 0" />
      <geometry>
        <mesh filename="file://$(find whc_description)/meshes/zhongbi.STL" />
      </geometry>
      <material name="">
        <color rgba="0.5 0.5 0.5 1"/>
      </material>
    </visual>
    <collision>
      <origin xyz="0 0 0" rpy="0 0 0" />
      <geometry>
        <mesh filename="file://$(find whc_description)/meshes/zhongbi.STL" />
      </geometry>
    </collision>
  </link>
  
  <joint name="joint3" type="revolute">
    <origin xyz="2.5 0 0" rpy="0 0 2.7263" />
    <parent link="link2" />
    <child link="link3" />
    <axis xyz="0 0 1" />
    <limit lower="-1.6895" upper="0" effort="100" velocity="5" />
  </joint>
  
  <link name="link4">
    <inertial>
      <origin xyz="-0.747 -0.400 0.058" rpy="0 0 0" />
      <mass value="700" />
      <inertia
        ixx="15.4283" ixy="15.3540" ixz="-6.045"
        iyy="153.4971" iyz="-1.9189" izz="162.7466" />
    </inertial>
    <visual>
      <origin xyz="0 0 0" rpy="0 0 0" />
      <geometry>
        <mesh filename="file://$(find whc_description)/meshes/xiaobi.STL" /> 
      </geometry>
      <material name="">
        <color rgba="0.5 0.5 0.5 1"/>
      </material>
    </visual>
    <collision>
      <origin xyz="0 0 0" rpy="0 0 0" />
      <geometry>
        <mesh filename="file://$(find whc_description)/meshes/xiaobi.STL" />  
      </geometry>
    </collision>
  </link>
  
  <joint name="joint4" type="revolute">
    <origin xyz="4.5 0 0" rpy="0 0 0.4815" />
    <parent link="link3" />
    <child link="link4" />
    <axis xyz="0 0 1" />
    <limit lower="0" upper="1.6265" effort="100" velocity="5" />
  </joint>
   
  <link name="link5">
    <inertial>
      <origin xyz="0.174 0 0" rpy="0 0 0" />
      <mass value="525" />
      <inertia
        ixx="3.918" ixy="0.036" ixz="0.016"
        iyy="7.31" iyz="0" izz="6.215" />
    </inertial>
    <visual>
      <origin xyz="0 0 0" rpy="0 0 0" />
      <geometry>
        <mesh filename="file://$(find whc_description)/meshes/R2.STL" />
      </geometry>
      <material name="">
        <color rgba="0.5 0.5 0.5 1"/>
      </material>
    </visual>
    <collision>
      <origin xyz="0 0 0" rpy="0 0 0" />
      <geometry>
        <mesh filename="file://$(find whc_description)/meshes/R2.STL" />
      </geometry>
    </collision>
  </link>
  
  <joint name="joint5" type="revolute">
    <origin xyz="1.855 -0.239 0" rpy="1.5708 0 0" />
    <parent link="link4" />
    <child link="link5" />
    <axis xyz="0 0 1" />
    <limit lower="-1.58" upper="1.58" effort="100" velocity="5" />
  </joint>
 
  <link name="link6">
    <inertial>
      <origin xyz="0 0.159 0" rpy="0 0 0" />
      <mass value="580" />
      <inertia
        ixx="1.176" ixy="0" ixz="0"
        iyy="0.991" iyz="0.0008" izz="0.432" />
    </inertial>
    <visual>
      <origin xyz="0 0 0" rpy="0 0 0" />
      <geometry>
        <mesh filename="file://$(find whc_description)/meshes/R1.STL" />
      </geometry>
      <material name="">
        <color rgba="0.5 0.5 0.5 1"/>
      </material>
    </visual>
    <collision>
      <origin xyz="0 0 0" rpy="0 0 0" />
      <geometry>
        <mesh filename="file://$(find whc_description)/meshes/R1.STL" />
      </geometry>
    </collision>
  </link>
  
  <joint name="joint6" type="revolute">
    <origin xyz="0.469 0 0" rpy="-1.5708 -1.5708 0" />
    <parent link="link5" />
    <child link="link6" />
    <axis xyz="0 0 1" />
    <limit lower="-1.58" upper="1.58" effort="100" velocity="3" />
  </joint>
   
  <link name="link7">
    <inertial>
      <origin xyz="0 0.35 0.522" rpy="0 0 0" />
      <mass value="720" />
      <inertia
        ixx="10.487" ixy="0" ixz="0"
        iyy="46.749" iyz="4.09" izz="43.742" />
    </inertial>
    <visual>
      <origin xyz="0 0 0" rpy="0 0 0" />
      <geometry>
        <mesh filename="file://$(find whc_description)/meshes/candou.STL" />
      </geometry>
      <material name="">
        <color rgba="0.5 0.5 0.5 1"/>
      </material>
    </visual>
    <collision>
      <origin xyz="0 0 0" rpy="0 0 0" />
      <geometry>
        <mesh filename="file://$(find whc_description)/meshes/candou.STL" />
      </geometry>
    </collision>
  </link>
  
  <joint name="joint7" type="revolute">
    <origin xyz="0 0.438 0" rpy="-1.5708 -1.5708 0" />
    <parent link="link6" />
    <child link="link7" />
    <axis xyz="0 0 1" />
    <limit lower="-3.14" upper="3.14" effort="100" velocity="3" />
  </joint>

  <!--底座的全局相机-->
  <!--link name="global_camera">
    <inertial>
      <origin xyz="0 0 0" rpy="0 0 0"/>
      <mass value="0.1"/>
      <inertia 
        ixx="0.0001" ixy="0.0" ixz="0.0"
        iyy="0.0001" iyz="0.0"
        izz="0.0001"/>
    </inertial>
    
    <visual>
      <origin xyz="0 0 0" rpy="0 0 0"/>
      <geometry>
        <cylinder radius="0.03" length="0.05"/>
      </geometry>
      <material name="global_cam_material">
        <color rgba="0.5 0.5 0.5 1"/>
      </material>
    </visual>
    
    <collision>
      <origin xyz="0 0 0" rpy="0 0 0"/>
      <geometry>
        <cylinder radius="0.03" length="0.05"/>
      </geometry>
    </collision>
  </link>

  <joint name="global_camera_joint" type="fixed">
    <parent link="base_link"/>  
    <child link="global_camera"/>
    <origin xyz="1.83 0 1.57" rpy="0 0 0"/>
  </joint-->

  <!--IMU-->
  <link name="imu_link">
    <visual>
      <geometry><box size="0.05 0.05 0.05"/></geometry>
    </visual>
  </link>

  <joint name="imu_joint" type="fixed">
    <parent link="base_link"/>
    <child link="imu_link"/>
    <origin xyz="0 0 1.65" rpy="0 0 0"/>
  </joint>

  <!-- 传动系统 -->
  <transmission name="left_back_trans">
    <type>transmission_interface/SimpleTransmission</type>
    <joint name="left_wheel_back_joint">
      <hardwareInterface>hardware_interface/velocity</hardwareInterface>
    </joint>
    <actuator name="left_back_motor">
      <hardwareInterface>hardware_interface/velocity</hardwareInterface>
      <mechanicalReduction>1</mechanicalReduction>
    </actuator>
  </transmission>

  <transmission name="left_middle_trans">
    <type>transmission_interface/SimpleTransmission</type>
    <joint name="left_wheel_middle_joint">
      <hardwareInterface>hardware_interface/velocity</hardwareInterface>
    </joint>
    <actuator name="left_middle_motor">
      <hardwareInterface>hardware_interface/velocity</hardwareInterface>
      <mechanicalReduction>1</mechanicalReduction>
    </actuator>
  </transmission>

  <transmission name="left_middle1_trans">
    <type>transmission_interface/SimpleTransmission</type>
    <joint name="left_wheel_middle1_joint">
      <hardwareInterface>hardware_interface/velocity</hardwareInterface>
    </joint>
    <actuator name="left_middle1_motor">
      <hardwareInterface>hardware_interface/velocity</hardwareInterface>
      <mechanicalReduction>1</mechanicalReduction>
    </actuator>
  </transmission>
  
  <transmission name="left_middle2_trans">
    <type>transmission_interface/SimpleTransmission</type>
    <joint name="left_wheel_middle2_joint">
      <hardwareInterface>hardware_interface/velocity</hardwareInterface>
    </joint>
    <actuator name="left_middle2_motor">
      <hardwareInterface>hardware_interface/velocity</hardwareInterface>
      <mechanicalReduction>1</mechanicalReduction>
    </actuator>
  </transmission>
  
  <transmission name="left_front_trans">
    <type>transmission_interface/SimpleTransmission</type>
    <joint name="left_wheel_front_joint">
      <hardwareInterface>hardware_interface/velocity</hardwareInterface>
    </joint>
    <actuator name="left_front_motor">
      <hardwareInterface>hardware_interface/velocity</hardwareInterface>
      <mechanicalReduction>1</mechanicalReduction>
    </actuator>
  </transmission>

  <transmission name="right_back_trans">
    <type>transmission_interface/SimpleTransmission</type>
    <joint name="right_wheel_back_joint">
      <hardwareInterface>hardware_interface/velocity</hardwareInterface>
    </joint>
    <actuator name="right_back_motor">
      <hardwareInterface>hardware_interface/velocity</hardwareInterface>
      <mechanicalReduction>1</mechanicalReduction>
    </actuator>
  </transmission>

  <transmission name="right_middle_trans">
    <type>transmission_interface/SimpleTransmission</type>
    <joint name="right_wheel_middle_joint">
      <hardwareInterface>hardware_interface/velocity</hardwareInterface>
    </joint>
    <actuator name="right_middle_motor">
      <hardwareInterface>hardware_interface/velocity</hardwareInterface>
      <mechanicalReduction>1</mechanicalReduction>
    </actuator>
  </transmission>

  <transmission name="right_middle1_trans">
    <type>transmission_interface/SimpleTransmission</type>
    <joint name="right_wheel_middle1_joint">
      <hardwareInterface>hardware_interface/velocity</hardwareInterface>
    </joint>
    <actuator name="right_middle1_motor">
      <hardwareInterface>hardware_interface/velocity</hardwareInterface>
      <mechanicalReduction>1</mechanicalReduction>
    </actuator>
  </transmission>

  <transmission name="right_middle2_trans">
    <type>transmission_interface/SimpleTransmission</type>
    <joint name="right_wheel_middle2_joint">
      <hardwareInterface>hardware_interface/velocity</hardwareInterface>
    </joint>
    <actuator name="right_middle2_motor">
      <hardwareInterface>hardware_interface/velocity</hardwareInterface>
      <mechanicalReduction>1</mechanicalReduction>
    </actuator>
  </transmission>
    
  <transmission name="right_front_trans">
    <type>transmission_interface/SimpleTransmission</type>
    <joint name="right_wheel_front_joint">
      <hardwareInterface>hardware_interface/velocity</hardwareInterface>
    </joint>
    <actuator name="right_front_motor">
      <hardwareInterface>hardware_interface/velocity</hardwareInterface>
      <mechanicalReduction>1</mechanicalReduction>
    </actuator>
  </transmission>

  <!-- 机械臂传动 - 保留位置和力矩接口 -->
  <transmission name="arm_joint1_trans">
    <type>transmission_interface/SimpleTransmission</type>
    <joint name="joint1">
      <hardwareInterface>hardware_interface/EffortJointInterface</hardwareInterface>
      <hardwareInterface>hardware_interface/PositionJointInterface</hardwareInterface>
    </joint>
    <actuator name="arm_joint1_motor">
      <hardwareInterface>hardware_interface/EffortJointInterface</hardwareInterface>
      <hardwareInterface>hardware_interface/PositionJointInterface</hardwareInterface>
      <mechanicalReduction>1</mechanicalReduction>
    </actuator>
  </transmission>

  <transmission name="arm_joint2_trans">
    <type>transmission_interface/SimpleTransmission</type>
    <joint name="joint2">
      <hardwareInterface>hardware_interface/EffortJointInterface</hardwareInterface>
      <hardwareInterface>hardware_interface/PositionJointInterface</hardwareInterface>
    </joint>
    <actuator name="arm_joint2_motor">
      <hardwareInterface>hardware_interface/EffortJointInterface</hardwareInterface>
      <hardwareInterface>hardware_interface/PositionJointInterface</hardwareInterface>
      <mechanicalReduction>1</mechanicalReduction>
    </actuator>
  </transmission>

  <transmission name="arm_joint3_trans">
    <type>transmission_interface/SimpleTransmission</type>
    <joint name="joint3">
      <hardwareInterface>hardware_interface/EffortJointInterface</hardwareInterface>
      <hardwareInterface>hardware_interface/PositionJointInterface</hardwareInterface>
    </joint>
    <actuator name="arm_joint3_motor">
      <hardwareInterface>hardware_interface/EffortJointInterface</hardwareInterface>
      <hardwareInterface>hardware_interface/PositionJointInterface</hardwareInterface>
      <mechanicalReduction>1</mechanicalReduction>
    </actuator>
  </transmission>

  <transmission name="arm_joint4_trans">
    <type>transmission_interface/SimpleTransmission</type>
    <joint name="joint4">
      <hardwareInterface>hardware_interface/EffortJointInterface</hardwareInterface>
      <hardwareInterface>hardware_interface/PositionJointInterface</hardwareInterface>
    </joint>
    <actuator name="arm_joint4_motor">
      <hardwareInterface>hardware_interface/EffortJointInterface</hardwareInterface>
      <hardwareInterface>hardware_interface/PositionJointInterface</hardwareInterface>
      <mechanicalReduction>1</mechanicalReduction>
    </actuator>
  </transmission>

  <transmission name="arm_joint5_trans">
    <type>transmission_interface/SimpleTransmission</type>
    <joint name="joint5">
      <hardwareInterface>hardware_interface/EffortJointInterface</hardwareInterface>
      <hardwareInterface>hardware_interface/PositionJointInterface</hardwareInterface>
    </joint>
    <actuator name="arm_joint5_motor">
      <hardwareInterface>hardware_interface/EffortJointInterface</hardwareInterface>
      <hardwareInterface>hardware_interface/PositionJointInterface</hardwareInterface>
      <mechanicalReduction>1</mechanicalReduction>
    </actuator>
  </transmission>

  <transmission name="arm_joint6_trans">
    <type>transmission_interface/SimpleTransmission</type>
    <joint name="joint6">
      <hardwareInterface>hardware_interface/EffortJointInterface</hardwareInterface>
      <hardwareInterface>hardware_interface/PositionJointInterface</hardwareInterface>
    </joint>
    <actuator name="arm_joint6_motor">
      <hardwareInterface>hardware_interface/EffortJointInterface</hardwareInterface>
      <hardwareInterface>hardware_interface/PositionJointInterface</hardwareInterface>
      <mechanicalReduction>1</mechanicalReduction>
    </actuator>
  </transmission>

  <transmission name="arm_joint7_trans">
    <type>transmission_interface/SimpleTransmission</type>
    <joint name="joint7">
      <hardwareInterface>hardware_interface/EffortJointInterface</hardwareInterface>
      <hardwareInterface>hardware_interface/PositionJointInterface</hardwareInterface>
    </joint>
    <actuator name="arm_joint7_motor">
      <hardwareInterface>hardware_interface/EffortJointInterface</hardwareInterface>
      <hardwareInterface>hardware_interface/PositionJointInterface</hardwareInterface>
      <mechanicalReduction>1</mechanicalReduction>
    </actuator>
  </transmission>

  <!-- ROS 2 控制系统 -->
  <ros2_control name="whc_control" type="system">
    <hardware>
      <plugin>gazebo_ros2_control/GazeboSystem</plugin>
    </hardware>
    
    <joint name="left_wheel_back_joint">
      <command_interface name="velocity"/>
      <state_interface name="position"/>
      <state_interface name="velocity"/>
    </joint>

    <joint name="left_wheel_middle_joint">
      <command_interface name="velocity"/>
      <state_interface name="position"/>
      <state_interface name="velocity"/>
    </joint>

    <joint name="left_wheel_middle1_joint">
      <command_interface name="velocity"/>
      <state_interface name="position"/>
      <state_interface name="velocity"/>
    </joint>

    <joint name="left_wheel_middle2_joint">
      <command_interface name="velocity"/>
      <state_interface name="position"/>
      <state_interface name="velocity"/>
    </joint>
   
    <joint name="left_wheel_front_joint">
      <command_interface name="velocity"/>
      <state_interface name="position"/>
      <state_interface name="velocity"/>
    </joint>
 
    <joint name="right_wheel_back_joint">
      <command_interface name="velocity"/>
      <state_interface name="position"/>
      <state_interface name="velocity"/>
    </joint>

    <joint name="right_wheel_middle_joint">
      <command_interface name="velocity"/>
      <state_interface name="position"/>
      <state_interface name="velocity"/>
    </joint>

    <joint name="right_wheel_middle1_joint">
      <command_interface name="velocity"/>
      <state_interface name="position"/>
      <state_interface name="velocity"/>
    </joint>

   
    <joint name="right_wheel_middle2_joint">
      <command_interface name="velocity"/>
      <state_interface name="position"/>
      <state_interface name="velocity"/>
    </joint>
    
    <joint name="right_wheel_front_joint">
      <command_interface name="velocity"/>
      <state_interface name="position"/>
      <state_interface name="velocity"/>
    </joint>

    <!-- 机械臂控制接口 -->
    <joint name="joint1">
      <command_interface name="position"/>
      <command_interface name="effort"/>
      <state_interface name="position"/>
      <state_interface name="velocity"/>
      <state_interface name="effort"/>
    </joint>
    
    <joint name="joint2">
      <command_interface name="position"/>
      <command_interface name="effort"/>
      <state_interface name="position"/>
      <state_interface name="velocity"/>
      <state_interface name="effort"/>
    </joint>
    
    <joint name="joint3">
      <command_interface name="position"/>
      <command_interface name="effort"/>
      <state_interface name="position"/>
      <state_interface name="velocity"/>
      <state_interface name="effort"/>
    </joint>
    
    <joint name="joint4">
      <command_interface name="position"/>
      <command_interface name="effort"/>
      <state_interface name="position"/>
      <state_interface name="velocity"/>
      <state_interface name="effort"/>
    </joint>
    
    <joint name="joint5">
      <command_interface name="position"/>
      <command_interface name="effort"/>
      <state_interface name="position"/>
      <state_interface name="velocity"/>
      <state_interface name="effort"/>
    </joint>
    
    <joint name="joint6">
      <command_interface name="position"/>
      <command_interface name="effort"/>
      <state_interface name="position"/>
      <state_interface name="velocity"/>
      <state_interface name="effort"/>
    </joint>
    
    <joint name="joint7">
      <command_interface name="position"/>
      <command_interface name="effort"/>
      <state_interface name="position"/>
      <state_interface name="velocity"/>
      <state_interface name="effort"/>
    </joint>
  </ros2_control>

  <!-- 为每个链接添加 Gazebo 材质定义 -->
  <gazebo reference="base_link">
    <material>Gazebo/Grey</material>
  </gazebo>

  <gazebo reference="link1">
    <material>Gazebo/Grey</material>
  </gazebo>

  <gazebo reference="link2">
    <material>Gazebo/Grey</material>
  </gazebo>

  <gazebo reference="link3">
    <material>Gazebo/Grey</material>
  </gazebo>

  <gazebo reference="link4">
    <material>Gazebo/Grey</material>
  </gazebo>

  <gazebo reference="link5">
    <material>Gazebo/Grey</material>
  </gazebo>

  <gazebo reference="link6">
    <material>Gazebo/Grey</material>
  </gazebo>

  <gazebo reference="link7">
    <material>Gazebo/Grey</material>
  </gazebo>

  <gazebo reference="right_wheel_back">
    <material>Gazebo/Grey</material>
    <mu1>1.0</mu1>
    <mu2>1.0</mu2>
    <kp>100000000.0</kp>
    <kd>1000000.0</kd>
  </gazebo>

  <gazebo reference="right_wheel_middle">
    <material>Gazebo/Grey</material>
    <mu1>1.0</mu1>
    <mu2>1.0</mu2>
    <kp>100000000.0</kp>
    <kd>1000000.0</kd>
  </gazebo>

  <gazebo reference="right_wheel_middle1">
    <material>Gazebo/Grey</material>
    <mu1>1.0</mu1>
    <mu2>1.0</mu2>
    <kp>100000000.0</kp>
    <kd>1000000.0</kd>
  </gazebo>

  <gazebo reference="right_wheel_middle2">
    <material>Gazebo/Grey</material>
    <mu1>1.0</mu1>
    <mu2>1.0</mu2>
    <kp>100000000.0</kp>
    <kd>1000000.0</kd>
  </gazebo>

  <gazebo reference="right_wheel_front">
    <material>Gazebo/Grey</material>
    <mu1>1.0</mu1>
    <mu2>1.0</mu2>
    <kp>100000000.0</kp>
    <kd>1000000.0</kd>
  </gazebo>

  <gazebo reference="left_wheel_back">
    <material>Gazebo/Grey</material>
    <mu1>1.0</mu1>
    <mu2>1.0</mu2>
    <kp>100000000.0</kp>
    <kd>1000000.0</kd>
  </gazebo>

  <gazebo reference="left_wheel_middle">
    <material>Gazebo/Grey</material>
    <mu1>1.0</mu1>
    <mu2>1.0</mu2>
    <kp>100000000.0</kp>
    <kd>1000000.0</kd>
  </gazebo>

  <gazebo reference="left_wheel_middle1">
    <material>Gazebo/Grey</material>
    <mu1>1.0</mu1>
    <mu2>1.0</mu2>
    <kp>100000000.0</kp>
    <kd>1000000.0</kd>
  </gazebo>

  <gazebo reference="left_wheel_middle2">
    <material>Gazebo/Grey</material>
    <mu1>1.0</mu1>
    <mu2>1.0</mu2>
    <kp>100000000.0</kp>
    <kd>1000000.0</kd>
  </gazebo>

  <gazebo reference="left_wheel_front">
    <material>Gazebo/Grey</material>
    <mu1>1.0</mu1>
    <mu2>1.0</mu2>
    <kp>100000000.0</kp>
    <kd>1000000.0</kd>
  </gazebo>

<!-- 激光雷达的Gazebo配置 -->
<!--gazebo reference="lidar_link">
  <sensor type="ray" name="lidar_sensor">
    <pose>0 0 0 0 0 0</pose>
    <visualize>true</visualize>
    <update_rate>10</update_rate>
    <ray>
      <scan>
        <horizontal>
          <samples>720</samples>
          <resolution>1</resolution>
          <min_angle>-3.14159</min_angle>
          <max_angle>3.14159</max_angle>
        </horizontal>
      </scan>
      <range>
        <min>0.20</min>
        <max>20.0</max>
        <resolution>0.01</resolution>
      </range>
      <noise>
        <type>gaussian</type>
        <mean>0.0</mean>
        <stddev>0.01</stddev>
      </noise>
    </ray>
    <plugin name="gazebo_ros_lidar_controller" filename="libgazebo_ros_ray_sensor.so">
      <ros>
        <namespace>/whc</namespace>
        <remapping>~/out:=scan</remapping>
      </ros>
      <output_type>sensor_msgs/LaserScan</output_type>
      <frame_name>lidar_link</frame_name>
    </plugin>
  </sensor>
  <material>Gazebo/Blue</material>
</gazebo-->

  <!-- 统一的 Gazebo 插件配置 -->
  <gazebo>
    <!-- Gazebo ROS 2 控制插件 -->
    <plugin name="gazebo_ros2_control" filename="libgazebo_ros2_control.so">
      <!-- <parameters>$(find whc_gazebo)/config/ros2_controllers.yaml</parameters> -->
    </plugin>

  </gazebo>

  <!-- 修改全局相机插件 -->
  <gazebo reference="global_camera">
    <material>Gazebo/Red</material>
    <sensor type="camera" name="global_camera_sensor">
      <update_rate>15</update_rate>
      <camera name="global">
        <horizontal_fov>1.91986</horizontal_fov>
        <image>
          <width>640</width>
          <height>480</height>
          <format>R8G8B8</format>
        </image>
        <clip>
          <near>0.1</near>
          <far>10.0</far>
        </clip>
      </camera>
      <!-- 使用ROS2兼容的插件 -->
      <plugin name="global_camera_controller" filename="libgazebo_ros_camera.so">
        <ros>
          <namespace>/whc</namespace>
        </ros>
        <camera_name>global_camera</camera_name>
        <frame_name>global_camera</frame_name>
        <image_topic_name>camera/global/image_raw</image_topic_name>
        <camera_info_topic_name>camera/global/camera_info</camera_info_topic_name>
        <update_rate>15</update_rate>
      </plugin>
    </sensor>
  </gazebo>

  <gazebo reference="imu_link">
    <sensor name="imu_sensor" type="imu">
      <always_on>true</always_on>
      <update_rate>100</update_rate>
      <visualize>true</visualize>
      <imu>
        <angular_velocity>
          <x>
            <noise type="gaussian">
              <mean>0.0</mean>
              <stddev>2e-4</stddev>
              <bias_mean>0.0000075</bias_mean>
              <bias_stddev>0.0000008</bias_stddev>
            </noise>
          </x>
          <y>
            <noise type="gaussian">
              <mean>0.0</mean>
              <stddev>2e-4</stddev>
              <bias_mean>0.0000075</bias_mean>
              <bias_stddev>0.0000008</bias_stddev>
            </noise>
          </y>
          <z>
            <noise type="gaussian">
              <mean>0.0</mean>
              <stddev>2e-4</stddev>
              <bias_mean>0.0000075</bias_mean>
              <bias_stddev>0.0000008</bias_stddev>
            </noise>
          </z>
        </angular_velocity>
        <linear_acceleration>
          <x>
            <noise type="gaussian">
              <mean>0.0</mean>
              <stddev>1.7e-2</stddev>
              <bias_mean>0.1</bias_mean>
              <bias_stddev>0.001</bias_stddev>
            </noise>
          </x>
          <y>
            <noise type="gaussian">
              <mean>0.0</mean>
              <stddev>1.7e-2</stddev>
              <bias_mean>0.1</bias_mean>
              <bias_stddev>0.001</bias_stddev>
            </noise>
          </y>
          <z>
            <noise type="gaussian">
              <mean>0.0</mean>
              <stddev>1.7e-2</stddev>
              <bias_mean>0.1</bias_mean>
              <bias_stddev>0.001</bias_stddev>
            </noise>
          </z>
        </linear_acceleration>
      </imu>
      <plugin name="imu_plugin" filename="libgazebo_ros_imu_sensor.so">
        <ros>
          <namespace>/</namespace>
          <remapping>~/out:=imu_data</remapping>
        </ros>
        <initial_orientation_as_reference>false</initial_orientation_as_reference>
      </plugin>
    </sensor>
  </gazebo>




  <!-- 包含激光雷达宏及实例化 -->

  <xacro:property name="PI" value="3.14159265359"/>
  <!-- ==================== 3D LiDAR Sensors ==================== -->
  <xacro:macro name="lidar_3d_fov" params="prefix x y z yaw">
    <link name="${prefix}_link">
      <visual>
        <geometry>
          <cylinder radius="0.03" length="0.05"/>
        </geometry>
        <material name="${prefix}_color">
          <color rgba="0.9 0.1 0.1 1.0"/>
        </material>
      </visual>
      <collision>
        <geometry>
          <cylinder radius="0.03" length="0.05"/>
        </geometry>
      </collision>
      <inertial>
        <mass value="0.05"/>
        <inertia ixx="0.00001" ixy="0" ixz="0" iyy="0.00001" iyz="0" izz="0.00001"/>
      </inertial>
    </link>

    <joint name="${prefix}_joint" type="fixed">
      <parent link="base_link"/>
      <child link="${prefix}_link"/>
      <origin xyz="${x} ${y} ${z}" rpy="0 0 ${yaw}"/>
    </joint>

    <gazebo reference="${prefix}_link">
      <material>Gazebo/Red</material>
      <sensor type="ray" name="${prefix}_sensor">
        <pose>0 0 0 0 0 0</pose>
        <visualize>false</visualize>
        <update_rate>10</update_rate>
        <ray>
          <scan>
            <horizontal>
              <samples>180</samples>
              <resolution>1</resolution>
              <min_angle>${-PI/2}</min_angle>
              <max_angle>${PI/2}</max_angle>
            </horizontal>
            <vertical>
              <samples>8</samples>
              <resolution>1</resolution>
              <min_angle>${-15.0*PI/180.0}</min_angle>
              <max_angle>${15.0*PI/180.0}</max_angle>
            </vertical>
          </scan>
          <range>
            <min>0.1</min>
            <max>30.0</max>
            <resolution>0.01</resolution>
          </range>
          <noise>
            <type>gaussian</type>
            <mean>0.0</mean>
            <stddev>0.005</stddev>
          </noise>
        </ray>
        <plugin name="${prefix}_plugin" filename="libgazebo_ros_ray_sensor.so">
          <ros>
            <remapping>~/out:=${prefix}/points</remapping>
          </ros>
          <output_type>sensor_msgs/PointCloud2</output_type>
          <frame_name>${prefix}_link</frame_name>
        </plugin>
      </sensor>
    </gazebo>
  </xacro:macro>

  <!-- lidar_1: 后 -->
  <xacro:lidar_3d_fov prefix="lidar_1" x="-2.5" y="0" z="1.5" yaw="${PI}"/>
  <!-- lidar_2: 左 -->
  <xacro:lidar_3d_fov prefix="lidar_2" x="0" y="1.8" z="1.5" yaw="${PI/2}"/>
  <!-- lidar_3: 前左 -->
  <xacro:lidar_3d_fov prefix="lidar_3" x="2.5" y="1.4" z="1.5" yaw="${PI/4}"/>
  <!-- lidar_4: 前右 -->
  <xacro:lidar_3d_fov prefix="lidar_4" x="2.5" y="-1.4" z="1.5" yaw="${-PI/4}"/>
  <!-- lidar_5: 右 -->
  <xacro:lidar_3d_fov prefix="lidar_5" x="0" y="-1.8" z="1.5" yaw="${-PI/2}"/>
</robot>